Workbook

Sheet Catalog
A1: rowid | B1: color | C1: rank | D1: wavelength_nm | E1: vf_typ_V | F1: vf_min_V | G1: vf_max_V | H1: imax_mA | I1: imax_source | J1: i_test_mA | K1: flux | L1: viewing_angle | M1: package | N1: price_USD | O1: n_leds | P1: color_group | Q1: notes
A2: 1015 | B2: Violet | C2: 1 | D2: 410nm dom/420nm peak | E2: 2.8 | F2: 2.8 | G2: 4 | H2: 30 | I2: datasheet | J2: 20 | K2: — | L2: 130° | M2: 0603 (1608) | N2: 0.415 | O2: 6 | P2: Violet | Q2: Confirmed: Imax=30mA, Pdmax=120mW, Vf 2.8-4.0V. Only true violet in catalog.
A3: 1012 | B3: Violet | C3: 2 | D3: 455nm dom | E3: 3 | F3: 2.8 | G3: 3.4 | H3: 100 | I3: estimated | J3: 60 | K3: 850 mcd | L3: 120° | M3: 1411 (3528) | N3: 0.29 | O3: 4 | P3: Violet | Q3: Imax estimated from package/test current.
A4: 4 | B4: Violet | C4: 3 | D4: 455nm (450-460nm) | E4: 2.96 | F4: 2.8 | G4: 3.2 | H4: 240 | I4: datasheet | J4: 140 | K4: 265 mW | L4: 124° | M4: 1411 (3528) | N4: 0.26 | O4: 4 | P4: Violet | Q4: Power LED. Budget-constrained to <50% Imax even at High level.
A5: 2 | B5: Blue | C5: 1 | D5: 475nm (470-480nm) | E5: 2.95 | F5: 2.75 | G5: 3.2 | H5: 240 | I5: datasheet | J5: 140 | K5: 20 lm | L5: 126° | M5: 1411 (3528) | N5: 0.24 | O5: 4 | P5: Blue
A6: 1014 | B6: Blue | C6: 2 | D6: 455nm dom | E6: 3.2 | F6: 3 | G6: 3.5 | H6: 200 | I6: estimated | J6: 150 | K6: 2100 mcd | L6: 120° | M6: 4-SMD J-Lead | N6: 0.4 | O6: 4 | P6: Blue | Q6: Imax estimated.
A7: 102 | B7: Blue | C7: 3 | D7: 465nm (460-470nm) | E7: 3.2 | F7: 3 | G7: 3.5 | H7: 200 | I7: datasheet | J7: 150 | K7: 11 lm | L7: 120° | M7: 1411 (3528) | N7: 0.32 | O7: 4 | P7: Blue
A8: 1 | B8: Green | C8: 1 | D8: 525nm (520-530nm) | E8: 2.8 | F8: 2.6 | G8: 3.2 | H8: 240 | I8: datasheet | J8: 140 | K8: 62 lm | L8: 124° | M8: 1411 (3528) | N8: 0.23 | O8: 4 | P8: Green | Q8: Best value in catalog.
A9: 532 | B9: Green | C9: 2 | D9: 525nm dom/515nm peak | E9: 3.1 | F9: 2.9 | G9: 3.5 | H9: 30 | I9: estimated | J9: 20 | K9: 1000 mcd | L9: 120° | M9: 1411 (3528) | N9: 0.19 | O9: 4 | P9: Green | Q9: Indicator class. Imax estimated.
A10: 783 | B10: Green | C10: 3 | D10: 525nm dom/520nm peak | E10: 3.4 | F10: 3.2 | G10: 3.8 | H10: 200 | I10: estimated | J10: 150 | K10: 8000 mcd | L10: 120° | M10: 1411 (3528) | N10: 0.36 | O10: 4 | P10: Green | Q10: High-brightness indicator. Imax estimated.
A11: 3 | B11: Red | C11: 1 | D11: 625nm (620-630nm) | E11: 2.2 | F11: 2 | G11: 2.6 | H11: 250 | I11: datasheet | J11: 140 | K11: 26 lm | L11: 122° | M11: 1411 (3528) | N11: 0.26 | O11: 4 | P11: Red | Q11: Perfect wavelength and price.
A12: 727 | B12: Red | C12: 2 | D12: 624nm dom/632nm peak | E12: 2 | F12: 1.8 | G12: 2.4 | H12: 200 | I12: estimated | J12: 150 | K12: 4500 mcd | L12: 120° | M12: 1411 (3528) | N12: 0.33 | O12: 4 | P12: Red | Q12: Lower Vf. Imax estimated.
A13: 6 | B13: Red | C13: 3 | D13: 620nm (typ) | E13: 2.2 | F13: 2 | G13: 2.6 | H13: 200 | I13: datasheet | J13: 150 | K13: 24 lm | L13: 120° | M13: 1411 (3528) | N13: 0.32 | O13: 4 | P13: Red | Q13: Lower Imax than row 3.

Sheet Calculator
A1: LED Color Analyzer — Driver Design Calculator
A3: Design Parameters
A4: Supply voltage (V) | C4: Vcc | D4: 4.5 | E4: V | F4: Exact 5V supply — no LDO possible (LDO needs Vin > Vout)
A5: Max total current budget (mA) | C5: Ibudg | D5: 500 | E5: mA | F5: 500mA available for LEDs (2.5A supply shared with RPi Zero 2W)
A6: Max exposure time (s) | C6: Texp | D6: 1.2 | E6: s | F6: Camera max exposure per channel
A7: Target brightness range | F7: Low≈40%, Med≈60%, High≈80% of Imax per LED
A9: E24 resistor series (Ω) — reference for R E24 column
D10: 1 | E10: 1.1 | F10: 1.2 | G10: 1.3 | H10: 1.5 | I10: 1.6 | J10: 1.8 | K10: 2 | L10: 2.2 | M10: 2.4 | N10: 2.7 | O10: 3 | P10: 3.3 | Q10: 3.6 | R10: 3.9 | S10: 4.3 | T10: 4.7 | U10: 5.1 | V10: 5.6 | W10: 6.2 | X10: 6.8 | Y10: 7.5 | Z10: 8.2 | AA10: 9.1 | AB10: 10 | AC10: 11 | AD10: 12 | AE10: 13 | AF10: 15 | AG10: 16 | AH10: 18 | AI10: 20 | AJ10: 22 | AK10: 24 | AL10: 27 | AM10: 30 | AN10: 33 | AO10: 36 | AP10: 39 | AQ10: 43 | AR10: 47 | AS10: 51 | AT10: 56 | AU10: 62 | AV10: 68 | AW10: 75 | AX10: 82 | AY10: 91 | AZ10: 100 | BA10: 110 | BB10: 120 | BC10: 130 | BD10: 150 | BE10: 160 | BF10: 180 | BG10: 200 | BH10: 220 | BI10: 240 | BJ10: 270 | BK10: 300 | BL10: 330 | BM10: 360 | BN10: 390 | BO10: 430 | BP10: 470 | BQ10: 510 | BR10: 560 | BS10: 620 | BT10: 680 | BU10: 750 | BV10: 820 | BW10: 910 | BX10: 1000
A13: Row ID (enter) | B13: Color Group | C13: Rank | D13: Wavelength | E13: Vf typ (V) | F13: Vf min (V) | G13: Vf max (V) | H13: Imax (mA) | I13: Imax source | J13: N LEDs | K13: Price $/LED | L13: Rel. Brightness (0–1) | M13: I target /LED (mA) | N13: R calc (Ω) | O13: R E24 (Ω) [suggest] | P13: I actual /LED (mA) | Q13: I total group (mA) | R13: % of Imax | S13: V drop across R (V) | T13: P per LED (mW) | U13: P resistor (mW) | V13: Budget OK? | W13: Warnings / Notes
E14: V | F14: V | G14: V | H14: mA | J14: # | K14: $ | L14: 0–1 | M14: mA | N14: Ω | O14: Ω | P14: mA | Q14: mA | R14: % | S14: V | T14: mW | U14: mW
A15: 1015 | B15: =IFERROR(INDEX(Catalog!$B:$B,MATCH(A15,Catalog!$A:$A,0)),"") -> Violet | C15: =IFERROR(INDEX(Catalog!$C:$C,MATCH(A15,Catalog!$A:$A,0)),"") -> 1 | D15: =IFERROR(INDEX(Catalog!$D:$D,MATCH(A15,Catalog!$A:$A,0)),"") -> 410nm dom/420nm peak | E15: =IFERROR(INDEX(Catalog!$E:$E,MATCH(A15,Catalog!$A:$A,0)),"") -> 2.8 | F15: =IFERROR(INDEX(Catalog!$F:$F,MATCH(A15,Catalog!$A:$A,0)),"") -> 2.8 | G15: =IFERROR(INDEX(Catalog!$G:$G,MATCH(A15,Catalog!$A:$A,0)),"") -> 4 | H15: =IFERROR(INDEX(Catalog!$H:$H,MATCH(A15,Catalog!$A:$A,0)),"") -> 30 | I15: =IFERROR(INDEX(Catalog!$I:$I,MATCH(A15,Catalog!$A:$A,0)),"") -> datasheet | J15: 4 | K15: =INDEX(Catalog!$N:$N,MATCH(A15,Catalog!$A:$A,0)) -> 0.415 | L15: 0.6 | M15: =H15*L15 -> 18 | N15: =($D$4-E15)/(M15/1000) -> 94.444444 | O15: {=IFERROR(INDEX($D$10:$BX$10,MATCH(MIN(ABS($D$10:$BX$10-N15)),ABS($D$10:$BX$10-N15),0)),N15)} -> 91 | P15: =($D$4-E15)/O15*1000 -> 18.681319 | Q15: =P15*J15 -> 74.725275 | R15: =P15/H15 -> 0.62271062 | S15: =P15/1000*O15 -> 1.7 | T15: =E15*P15 -> 52.307692 | U15: =(P15/1000)^2*O15*1000 -> 31.758242 | V15: =IFERROR(IF(Q15<=$D$5,"OK","OVER"),"--") -> OK | W15: =TRIM(IF(I15="estimated","* Imax estimated","")&IF(ISNUMBER(Q15),IF(Q15>$D$5," | OVER BUDGET",""),"")&IF(ISNUMBER(R15),IF(R15>0.85," | >85% Imax",""),"")&IF(AND(ISNUMBER(G15),ISNUMBER(E15)),IF(G15-E15>0.5," | Wide Vf range",""),"")&IF(ISNUMBER(U15),IF(U15>250," | R>250mW: use 1206",""),"")) -> | Wide Vf range
A16: 1015 | B16: =IFERROR(INDEX(Catalog!$B:$B,MATCH(A16,Catalog!$A:$A,0)),"") -> Violet | C16: =IFERROR(INDEX(Catalog!$C:$C,MATCH(A16,Catalog!$A:$A,0)),"") -> 1 | D16: =IFERROR(INDEX(Catalog!$D:$D,MATCH(A16,Catalog!$A:$A,0)),"") -> 410nm dom/420nm peak | E16: =IFERROR(INDEX(Catalog!$E:$E,MATCH(A16,Catalog!$A:$A,0)),"") -> 2.8 | F16: =IFERROR(INDEX(Catalog!$F:$F,MATCH(A16,Catalog!$A:$A,0)),"") -> 2.8 | G16: =IFERROR(INDEX(Catalog!$G:$G,MATCH(A16,Catalog!$A:$A,0)),"") -> 4 | H16: =IFERROR(INDEX(Catalog!$H:$H,MATCH(A16,Catalog!$A:$A,0)),"") -> 30 | I16: =IFERROR(INDEX(Catalog!$I:$I,MATCH(A16,Catalog!$A:$A,0)),"") -> datasheet | J16: 6 | K16: =IFERROR(INDEX(Catalog!$N:$N,MATCH(A16,Catalog!$A:$A,0)),"") -> 0.415 | L16: 0.6 | M16: =IFERROR(H16*L16,"") -> 18 | N16: =IFERROR(($D$4-E16)/(M16/1000),"") -> 94.444444 | O16: {=IFERROR(INDEX($D$10:$BX$10,MATCH(MIN(ABS($D$10:$BX$10-N16)),ABS($D$10:$BX$10-N16),0)),N16)} -> 91 | P16: =IFERROR(($D$4-E16)/O16*1000,"") -> 18.681319 | Q16: =IFERROR(P16*J16,"") -> 112.08791 | R16: =IFERROR(P16/H16,"") -> 0.62271062 | S16: =IFERROR(P16/1000*O16,"") -> 1.7 | T16: =IFERROR(E16*P16,"") -> 52.307692 | U16: =IFERROR((P16/1000)^2*O16*1000,"") -> 31.758242 | V16: =IFERROR(IF(Q16<=$D$5,"OK","OVER"),"--") -> OK | W16: =TRIM(IF(I16="estimated","* Imax estimated","")&IF(ISNUMBER(Q16),IF(Q16>$D$5," | OVER BUDGET",""),"")&IF(ISNUMBER(R16),IF(R16>0.85," | >85% Imax",""),"")&IF(AND(ISNUMBER(G16),ISNUMBER(E16)),IF(G16-E16>0.5," | Wide Vf range",""),"")&IF(ISNUMBER(U16),IF(U16>250," | R>250mW: use 1206",""),"")) -> | Wide Vf range
A17: 1012 | B17: =IFERROR(INDEX(Catalog!$B:$B,MATCH(A17,Catalog!$A:$A,0)),"") -> Violet | C17: =IFERROR(INDEX(Catalog!$C:$C,MATCH(A17,Catalog!$A:$A,0)),"") -> 2 | D17: =IFERROR(INDEX(Catalog!$D:$D,MATCH(A17,Catalog!$A:$A,0)),"") -> 455nm dom | E17: =IFERROR(INDEX(Catalog!$E:$E,MATCH(A17,Catalog!$A:$A,0)),"") -> 3 | F17: =IFERROR(INDEX(Catalog!$F:$F,MATCH(A17,Catalog!$A:$A,0)),"") -> 2.8 | G17: =IFERROR(INDEX(Catalog!$G:$G,MATCH(A17,Catalog!$A:$A,0)),"") -> 3.4 | H17: =IFERROR(INDEX(Catalog!$H:$H,MATCH(A17,Catalog!$A:$A,0)),"") -> 100 | I17: =IFERROR(INDEX(Catalog!$I:$I,MATCH(A17,Catalog!$A:$A,0)),"") -> estimated | J17: 4 | K17: =IFERROR(INDEX(Catalog!$N:$N,MATCH(A17,Catalog!$A:$A,0)),"") -> 0.29 | L17: 0.6 | M17: =IFERROR(H17*L17,"") -> 60 | N17: =IFERROR(($D$4-E17)/(M17/1000),"") -> 25 | O17: {=IFERROR(INDEX($D$10:$BX$10,MATCH(MIN(ABS($D$10:$BX$10-N17)),ABS($D$10:$BX$10-N17),0)),N17)} -> 24 | P17: =IFERROR(($D$4-E17)/O17*1000,"") -> 62.5 | Q17: =IFERROR(P17*J17,"") -> 250 | R17: =IFERROR(P17/H17,"") -> 0.625 | S17: =IFERROR(P17/1000*O17,"") -> 1.5 | T17: =IFERROR(E17*P17,"") -> 187.5 | U17: =IFERROR((P17/1000)^2*O17*1000,"") -> 93.75 | V17: =IFERROR(IF(Q17<=$D$5,"OK","OVER"),"--") -> OK | W17: =TRIM(IF(I17="estimated","* Imax estimated","")&IF(ISNUMBER(Q17),IF(Q17>$D$5," | OVER BUDGET",""),"")&IF(ISNUMBER(R17),IF(R17>0.85," | >85% Imax",""),"")&IF(AND(ISNUMBER(G17),ISNUMBER(E17)),IF(G17-E17>0.5," | Wide Vf range",""),"")&IF(ISNUMBER(U17),IF(U17>250," | R>250mW: use 1206",""),"")) -> * Imax estimated
A18: 1012 | B18: =IFERROR(INDEX(Catalog!$B:$B,MATCH(A18,Catalog!$A:$A,0)),"") -> Violet | C18: =IFERROR(INDEX(Catalog!$C:$C,MATCH(A18,Catalog!$A:$A,0)),"") -> 2 | D18: =IFERROR(INDEX(Catalog!$D:$D,MATCH(A18,Catalog!$A:$A,0)),"") -> 455nm dom | E18: =IFERROR(INDEX(Catalog!$E:$E,MATCH(A18,Catalog!$A:$A,0)),"") -> 3 | F18: =IFERROR(INDEX(Catalog!$F:$F,MATCH(A18,Catalog!$A:$A,0)),"") -> 2.8 | G18: =IFERROR(INDEX(Catalog!$G:$G,MATCH(A18,Catalog!$A:$A,0)),"") -> 3.4 | H18: =IFERROR(INDEX(Catalog!$H:$H,MATCH(A18,Catalog!$A:$A,0)),"") -> 100 | I18: =IFERROR(INDEX(Catalog!$I:$I,MATCH(A18,Catalog!$A:$A,0)),"") -> estimated | J18: 6 | K18: =IFERROR(INDEX(Catalog!$N:$N,MATCH(A18,Catalog!$A:$A,0)),"") -> 0.29 | L18: 0.6 | M18: =IFERROR(H18*L18,"") -> 60 | N18: =IFERROR(($D$4-E18)/(M18/1000),"") -> 25 | O18: {=IFERROR(INDEX($D$10:$BX$10,MATCH(MIN(ABS($D$10:$BX$10-N18)),ABS($D$10:$BX$10-N18),0)),N18)} -> 24 | P18: =IFERROR(($D$4-E18)/O18*1000,"") -> 62.5 | Q18: =IFERROR(P18*J18,"") -> 375 | R18: =IFERROR(P18/H18,"") -> 0.625 | S18: =IFERROR(P18/1000*O18,"") -> 1.5 | T18: =IFERROR(E18*P18,"") -> 187.5 | U18: =IFERROR((P18/1000)^2*O18*1000,"") -> 93.75 | V18: =IFERROR(IF(Q18<=$D$5,"OK","OVER"),"--") -> OK | W18: =TRIM(IF(I18="estimated","* Imax estimated","")&IF(ISNUMBER(Q18),IF(Q18>$D$5," | OVER BUDGET",""),"")&IF(ISNUMBER(R18),IF(R18>0.85," | >85% Imax",""),"")&IF(AND(ISNUMBER(G18),ISNUMBER(E18)),IF(G18-E18>0.5," | Wide Vf range",""),"")&IF(ISNUMBER(U18),IF(U18>250," | R>250mW: use 1206",""),"")) -> * Imax estimated
A19: 4 | B19: =IFERROR(INDEX(Catalog!$B:$B,MATCH(A19,Catalog!$A:$A,0)),"") -> Violet | C19: =IFERROR(INDEX(Catalog!$C:$C,MATCH(A19,Catalog!$A:$A,0)),"") -> 3 | D19: =IFERROR(INDEX(Catalog!$D:$D,MATCH(A19,Catalog!$A:$A,0)),"") -> 455nm (450-460nm) | E19: =IFERROR(INDEX(Catalog!$E:$E,MATCH(A19,Catalog!$A:$A,0)),"") -> 2.96 | F19: =IFERROR(INDEX(Catalog!$F:$F,MATCH(A19,Catalog!$A:$A,0)),"") -> 2.8 | G19: =IFERROR(INDEX(Catalog!$G:$G,MATCH(A19,Catalog!$A:$A,0)),"") -> 3.2 | H19: =IFERROR(INDEX(Catalog!$H:$H,MATCH(A19,Catalog!$A:$A,0)),"") -> 240 | I19: =IFERROR(INDEX(Catalog!$I:$I,MATCH(A19,Catalog!$A:$A,0)),"") -> datasheet | J19: 4 | K19: =IFERROR(INDEX(Catalog!$N:$N,MATCH(A19,Catalog!$A:$A,0)),"") -> 0.26 | L19: 0.6 | M19: =IFERROR(H19*L19,"") -> 144 | N19: =IFERROR(($D$4-E19)/(M19/1000),"") -> 10.694444 | O19: {=IFERROR(INDEX($D$10:$BX$10,MATCH(MIN(ABS($D$10:$BX$10-N19)),ABS($D$10:$BX$10-N19),0)),N19)} -> 11 | P19: =IFERROR(($D$4-E19)/O19*1000,"") -> 140 | Q19: =IFERROR(P19*J19,"") -> 560 | R19: =IFERROR(P19/H19,"") -> 0.58333333 | S19: =IFERROR(P19/1000*O19,"") -> 1.54 | T19: =IFERROR(E19*P19,"") -> 414.4 | U19: =IFERROR((P19/1000)^2*O19*1000,"") -> 215.6 | V19: =IFERROR(IF(Q19<=$D$5,"OK","OVER"),"--") -> OVER | W19: =TRIM(IF(I19="estimated","* Imax estimated","")&IF(ISNUMBER(Q19),IF(Q19>$D$5," | OVER BUDGET",""),"")&IF(ISNUMBER(R19),IF(R19>0.85," | >85% Imax",""),"")&IF(AND(ISNUMBER(G19),ISNUMBER(E19)),IF(G19-E19>0.5," | Wide Vf range",""),"")&IF(ISNUMBER(U19),IF(U19>250," | R>250mW: use 1206",""),"")) -> | OVER BUDGET
A20: 4 | B20: =IFERROR(INDEX(Catalog!$B:$B,MATCH(A20,Catalog!$A:$A,0)),"") -> Violet | C20: =IFERROR(INDEX(Catalog!$C:$C,MATCH(A20,Catalog!$A:$A,0)),"") -> 3 | D20: =IFERROR(INDEX(Catalog!$D:$D,MATCH(A20,Catalog!$A:$A,0)),"") -> 455nm (450-460nm) | E20: =IFERROR(INDEX(Catalog!$E:$E,MATCH(A20,Catalog!$A:$A,0)),"") -> 2.96 | F20: =IFERROR(INDEX(Catalog!$F:$F,MATCH(A20,Catalog!$A:$A,0)),"") -> 2.8 | G20: =IFERROR(INDEX(Catalog!$G:$G,MATCH(A20,Catalog!$A:$A,0)),"") -> 3.2 | H20: =IFERROR(INDEX(Catalog!$H:$H,MATCH(A20,Catalog!$A:$A,0)),"") -> 240 | I20: =IFERROR(INDEX(Catalog!$I:$I,MATCH(A20,Catalog!$A:$A,0)),"") -> datasheet | J20: 6 | K20: =IFERROR(INDEX(Catalog!$N:$N,MATCH(A20,Catalog!$A:$A,0)),"") -> 0.26 | L20: 0.6 | M20: =IFERROR(H20*L20,"") -> 144 | N20: =IFERROR(($D$4-E20)/(M20/1000),"") -> 10.694444 | O20: {=IFERROR(INDEX($D$10:$BX$10,MATCH(MIN(ABS($D$10:$BX$10-N20)),ABS($D$10:$BX$10-N20),0)),N20)} -> 11 | P20: =IFERROR(($D$4-E20)/O20*1000,"") -> 140 | Q20: =IFERROR(P20*J20,"") -> 840 | R20: =IFERROR(P20/H20,"") -> 0.58333333 | S20: =IFERROR(P20/1000*O20,"") -> 1.54 | T20: =IFERROR(E20*P20,"") -> 414.4 | U20: =IFERROR((P20/1000)^2*O20*1000,"") -> 215.6 | V20: =IFERROR(IF(Q20<=$D$5,"OK","OVER"),"--") -> OVER | W20: =TRIM(IF(I20="estimated","* Imax estimated","")&IF(ISNUMBER(Q20),IF(Q20>$D$5," | OVER BUDGET",""),"")&IF(ISNUMBER(R20),IF(R20>0.85," | >85% Imax",""),"")&IF(AND(ISNUMBER(G20),ISNUMBER(E20)),IF(G20-E20>0.5," | Wide Vf range",""),"")&IF(ISNUMBER(U20),IF(U20>250," | R>250mW: use 1206",""),"")) -> | OVER BUDGET
A21: 2 | B21: =IFERROR(INDEX(Catalog!$B:$B,MATCH(A21,Catalog!$A:$A,0)),"") -> Blue | C21: =IFERROR(INDEX(Catalog!$C:$C,MATCH(A21,Catalog!$A:$A,0)),"") -> 1 | D21: =IFERROR(INDEX(Catalog!$D:$D,MATCH(A21,Catalog!$A:$A,0)),"") -> 475nm (470-480nm) | E21: =IFERROR(INDEX(Catalog!$E:$E,MATCH(A21,Catalog!$A:$A,0)),"") -> 2.95 | F21: =IFERROR(INDEX(Catalog!$F:$F,MATCH(A21,Catalog!$A:$A,0)),"") -> 2.75 | G21: =IFERROR(INDEX(Catalog!$G:$G,MATCH(A21,Catalog!$A:$A,0)),"") -> 3.2 | H21: =IFERROR(INDEX(Catalog!$H:$H,MATCH(A21,Catalog!$A:$A,0)),"") -> 240 | I21: =IFERROR(INDEX(Catalog!$I:$I,MATCH(A21,Catalog!$A:$A,0)),"") -> datasheet | J21: 4 | K21: =IFERROR(INDEX(Catalog!$N:$N,MATCH(A21,Catalog!$A:$A,0)),"") -> 0.24 | L21: 0.6 | M21: =IFERROR(H21*L21,"") -> 144 | N21: =IFERROR(($D$4-E21)/(M21/1000),"") -> 10.763889 | O21: {=IFERROR(INDEX($D$10:$BX$10,MATCH(MIN(ABS($D$10:$BX$10-N21)),ABS($D$10:$BX$10-N21),0)),N21)} -> 11 | P21: =IFERROR(($D$4-E21)/O21*1000,"") -> 140.90909 | Q21: =IFERROR(P21*J21,"") -> 563.63636 | R21: =IFERROR(P21/H21,"") -> 0.58712121 | S21: =IFERROR(P21/1000*O21,"") -> 1.55 | T21: =IFERROR(E21*P21,"") -> 415.68182 | U21: =IFERROR((P21/1000)^2*O21*1000,"") -> 218.40909 | V21: =IFERROR(IF(Q21<=$D$5,"OK","OVER"),"--") -> OVER | W21: =TRIM(IF(I21="estimated","* Imax estimated","")&IF(ISNUMBER(Q21),IF(Q21>$D$5," | OVER BUDGET",""),"")&IF(ISNUMBER(R21),IF(R21>0.85," | >85% Imax",""),"")&IF(AND(ISNUMBER(G21),ISNUMBER(E21)),IF(G21-E21>0.5," | Wide Vf range",""),"")&IF(ISNUMBER(U21),IF(U21>250," | R>250mW: use 1206",""),"")) -> | OVER BUDGET
A22: 1014 | B22: =IFERROR(INDEX(Catalog!$B:$B,MATCH(A22,Catalog!$A:$A,0)),"") -> Blue | C22: =IFERROR(INDEX(Catalog!$C:$C,MATCH(A22,Catalog!$A:$A,0)),"") -> 2 | D22: =IFERROR(INDEX(Catalog!$D:$D,MATCH(A22,Catalog!$A:$A,0)),"") -> 455nm dom | E22: =IFERROR(INDEX(Catalog!$E:$E,MATCH(A22,Catalog!$A:$A,0)),"") -> 3.2 | F22: =IFERROR(INDEX(Catalog!$F:$F,MATCH(A22,Catalog!$A:$A,0)),"") -> 3 | G22: =IFERROR(INDEX(Catalog!$G:$G,MATCH(A22,Catalog!$A:$A,0)),"") -> 3.5 | H22: =IFERROR(INDEX(Catalog!$H:$H,MATCH(A22,Catalog!$A:$A,0)),"") -> 200 | I22: =IFERROR(INDEX(Catalog!$I:$I,MATCH(A22,Catalog!$A:$A,0)),"") -> estimated | J22: 4 | K22: =IFERROR(INDEX(Catalog!$N:$N,MATCH(A22,Catalog!$A:$A,0)),"") -> 0.4 | L22: 0.6 | M22: =IFERROR(H22*L22,"") -> 120 | N22: =IFERROR(($D$4-E22)/(M22/1000),"") -> 10.833333 | O22: {=IFERROR(INDEX($D$10:$BX$10,MATCH(MIN(ABS($D$10:$BX$10-N22)),ABS($D$10:$BX$10-N22),0)),N22)} -> 11 | P22: =IFERROR(($D$4-E22)/O22*1000,"") -> 118.18182 | Q22: =IFERROR(P22*J22,"") -> 472.72727 | R22: =IFERROR(P22/H22,"") -> 0.59090909 | S22: =IFERROR(P22/1000*O22,"") -> 1.3 | T22: =IFERROR(E22*P22,"") -> 378.18182 | U22: =IFERROR((P22/1000)^2*O22*1000,"") -> 153.63636 | V22: =IFERROR(IF(Q22<=$D$5,"OK","OVER"),"--") -> OK | W22: =TRIM(IF(I22="estimated","* Imax estimated","")&IF(ISNUMBER(Q22),IF(Q22>$D$5," | OVER BUDGET",""),"")&IF(ISNUMBER(R22),IF(R22>0.85," | >85% Imax",""),"")&IF(AND(ISNUMBER(G22),ISNUMBER(E22)),IF(G22-E22>0.5," | Wide Vf range",""),"")&IF(ISNUMBER(U22),IF(U22>250," | R>250mW: use 1206",""),"")) -> * Imax estimated
A23: 102 | B23: =IFERROR(INDEX(Catalog!$B:$B,MATCH(A23,Catalog!$A:$A,0)),"") -> Blue | C23: =IFERROR(INDEX(Catalog!$C:$C,MATCH(A23,Catalog!$A:$A,0)),"") -> 3 | D23: =IFERROR(INDEX(Catalog!$D:$D,MATCH(A23,Catalog!$A:$A,0)),"") -> 465nm (460-470nm) | E23: =IFERROR(INDEX(Catalog!$E:$E,MATCH(A23,Catalog!$A:$A,0)),"") -> 3.2 | F23: =IFERROR(INDEX(Catalog!$F:$F,MATCH(A23,Catalog!$A:$A,0)),"") -> 3 | G23: =IFERROR(INDEX(Catalog!$G:$G,MATCH(A23,Catalog!$A:$A,0)),"") -> 3.5 | H23: =IFERROR(INDEX(Catalog!$H:$H,MATCH(A23,Catalog!$A:$A,0)),"") -> 200 | I23: =IFERROR(INDEX(Catalog!$I:$I,MATCH(A23,Catalog!$A:$A,0)),"") -> datasheet | J23: 4 | K23: =IFERROR(INDEX(Catalog!$N:$N,MATCH(A23,Catalog!$A:$A,0)),"") -> 0.32 | L23: 0.6 | M23: =IFERROR(H23*L23,"") -> 120 | N23: =IFERROR(($D$4-E23)/(M23/1000),"") -> 10.833333 | O23: {=IFERROR(INDEX($D$10:$BX$10,MATCH(MIN(ABS($D$10:$BX$10-N23)),ABS($D$10:$BX$10-N23),0)),N23)} -> 11 | P23: =IFERROR(($D$4-E23)/O23*1000,"") -> 118.18182 | Q23: =IFERROR(P23*J23,"") -> 472.72727 | R23: =IFERROR(P23/H23,"") -> 0.59090909 | S23: =IFERROR(P23/1000*O23,"") -> 1.3 | T23: =IFERROR(E23*P23,"") -> 378.18182 | U23: =IFERROR((P23/1000)^2*O23*1000,"") -> 153.63636 | V23: =IFERROR(IF(Q23<=$D$5,"OK","OVER"),"--") -> OK | W23: =TRIM(IF(I23="estimated","* Imax estimated","")&IF(ISNUMBER(Q23),IF(Q23>$D$5," | OVER BUDGET",""),"")&IF(ISNUMBER(R23),IF(R23>0.85," | >85% Imax",""),"")&IF(AND(ISNUMBER(G23),ISNUMBER(E23)),IF(G23-E23>0.5," | Wide Vf range",""),"")&IF(ISNUMBER(U23),IF(U23>250," | R>250mW: use 1206",""),""))
A24: 1 | B24: =IFERROR(INDEX(Catalog!$B:$B,MATCH(A24,Catalog!$A:$A,0)),"") -> Green | C24: =IFERROR(INDEX(Catalog!$C:$C,MATCH(A24,Catalog!$A:$A,0)),"") -> 1 | D24: =IFERROR(INDEX(Catalog!$D:$D,MATCH(A24,Catalog!$A:$A,0)),"") -> 525nm (520-530nm) | E24: =IFERROR(INDEX(Catalog!$E:$E,MATCH(A24,Catalog!$A:$A,0)),"") -> 2.8 | F24: =IFERROR(INDEX(Catalog!$F:$F,MATCH(A24,Catalog!$A:$A,0)),"") -> 2.6 | G24: =IFERROR(INDEX(Catalog!$G:$G,MATCH(A24,Catalog!$A:$A,0)),"") -> 3.2 | H24: =IFERROR(INDEX(Catalog!$H:$H,MATCH(A24,Catalog!$A:$A,0)),"") -> 240 | I24: =IFERROR(INDEX(Catalog!$I:$I,MATCH(A24,Catalog!$A:$A,0)),"") -> datasheet | J24: 4 | K24: =IFERROR(INDEX(Catalog!$N:$N,MATCH(A24,Catalog!$A:$A,0)),"") -> 0.23 | L24: 0.6 | M24: =IFERROR(H24*L24,"") -> 144 | N24: =IFERROR(($D$4-E24)/(M24/1000),"") -> 11.805556 | O24: {=IFERROR(INDEX($D$10:$BX$10,MATCH(MIN(ABS($D$10:$BX$10-N24)),ABS($D$10:$BX$10-N24),0)),N24)} -> 12 | P24: =IFERROR(($D$4-E24)/O24*1000,"") -> 141.66667 | Q24: =IFERROR(P24*J24,"") -> 566.66667 | R24: =IFERROR(P24/H24,"") -> 0.59027778 | S24: =IFERROR(P24/1000*O24,"") -> 1.7 | T24: =IFERROR(E24*P24,"") -> 396.66667 | U24: =IFERROR((P24/1000)^2*O24*1000,"") -> 240.83333 | V24: =IFERROR(IF(Q24<=$D$5,"OK","OVER"),"--") -> OVER | W24: =TRIM(IF(I24="estimated","* Imax estimated","")&IF(ISNUMBER(Q24),IF(Q24>$D$5," | OVER BUDGET",""),"")&IF(ISNUMBER(R24),IF(R24>0.85," | >85% Imax",""),"")&IF(AND(ISNUMBER(G24),ISNUMBER(E24)),IF(G24-E24>0.5," | Wide Vf range",""),"")&IF(ISNUMBER(U24),IF(U24>250," | R>250mW: use 1206",""),"")) -> | OVER BUDGET
A25: 532 | B25: =IFERROR(INDEX(Catalog!$B:$B,MATCH(A25,Catalog!$A:$A,0)),"") -> Green | C25: =IFERROR(INDEX(Catalog!$C:$C,MATCH(A25,Catalog!$A:$A,0)),"") -> 2 | D25: =IFERROR(INDEX(Catalog!$D:$D,MATCH(A25,Catalog!$A:$A,0)),"") -> 525nm dom/515nm peak | E25: =IFERROR(INDEX(Catalog!$E:$E,MATCH(A25,Catalog!$A:$A,0)),"") -> 3.1 | F25: =IFERROR(INDEX(Catalog!$F:$F,MATCH(A25,Catalog!$A:$A,0)),"") -> 2.9 | G25: =IFERROR(INDEX(Catalog!$G:$G,MATCH(A25,Catalog!$A:$A,0)),"") -> 3.5 | H25: =IFERROR(INDEX(Catalog!$H:$H,MATCH(A25,Catalog!$A:$A,0)),"") -> 30 | I25: =IFERROR(INDEX(Catalog!$I:$I,MATCH(A25,Catalog!$A:$A,0)),"") -> estimated | J25: 4 | K25: =IFERROR(INDEX(Catalog!$N:$N,MATCH(A25,Catalog!$A:$A,0)),"") -> 0.19 | L25: 0.6 | M25: =IFERROR(H25*L25,"") -> 18 | N25: =IFERROR(($D$4-E25)/(M25/1000),"") -> 77.777778 | O25: {=IFERROR(INDEX($D$10:$BX$10,MATCH(MIN(ABS($D$10:$BX$10-N25)),ABS($D$10:$BX$10-N25),0)),N25)} -> 75 | P25: =IFERROR(($D$4-E25)/O25*1000,"") -> 18.666667 | Q25: =IFERROR(P25*J25,"") -> 74.666667 | R25: =IFERROR(P25/H25,"") -> 0.62222222 | S25: =IFERROR(P25/1000*O25,"") -> 1.4 | T25: =IFERROR(E25*P25,"") -> 57.866667 | U25: =IFERROR((P25/1000)^2*O25*1000,"") -> 26.133333 | V25: =IFERROR(IF(Q25<=$D$5,"OK","OVER"),"--") -> OK | W25: =TRIM(IF(I25="estimated","* Imax estimated","")&IF(ISNUMBER(Q25),IF(Q25>$D$5," | OVER BUDGET",""),"")&IF(ISNUMBER(R25),IF(R25>0.85," | >85% Imax",""),"")&IF(AND(ISNUMBER(G25),ISNUMBER(E25)),IF(G25-E25>0.5," | Wide Vf range",""),"")&IF(ISNUMBER(U25),IF(U25>250," | R>250mW: use 1206",""),"")) -> * Imax estimated
A26: 783 | B26: =IFERROR(INDEX(Catalog!$B:$B,MATCH(A26,Catalog!$A:$A,0)),"") -> Green | C26: =IFERROR(INDEX(Catalog!$C:$C,MATCH(A26,Catalog!$A:$A,0)),"") -> 3 | D26: =IFERROR(INDEX(Catalog!$D:$D,MATCH(A26,Catalog!$A:$A,0)),"") -> 525nm dom/520nm peak | E26: =IFERROR(INDEX(Catalog!$E:$E,MATCH(A26,Catalog!$A:$A,0)),"") -> 3.4 | F26: =IFERROR(INDEX(Catalog!$F:$F,MATCH(A26,Catalog!$A:$A,0)),"") -> 3.2 | G26: =IFERROR(INDEX(Catalog!$G:$G,MATCH(A26,Catalog!$A:$A,0)),"") -> 3.8 | H26: =IFERROR(INDEX(Catalog!$H:$H,MATCH(A26,Catalog!$A:$A,0)),"") -> 200 | I26: =IFERROR(INDEX(Catalog!$I:$I,MATCH(A26,Catalog!$A:$A,0)),"") -> estimated | J26: 4 | K26: =IFERROR(INDEX(Catalog!$N:$N,MATCH(A26,Catalog!$A:$A,0)),"") -> 0.36 | L26: 0.6 | M26: =IFERROR(H26*L26,"") -> 120 | N26: =IFERROR(($D$4-E26)/(M26/1000),"") -> 9.1666667 | O26: {=IFERROR(INDEX($D$10:$BX$10,MATCH(MIN(ABS($D$10:$BX$10-N26)),ABS($D$10:$BX$10-N26),0)),N26)} -> 9.1 | P26: =IFERROR(($D$4-E26)/O26*1000,"") -> 120.87912 | Q26: =IFERROR(P26*J26,"") -> 483.51648 | R26: =IFERROR(P26/H26,"") -> 0.6043956 | S26: =IFERROR(P26/1000*O26,"") -> 1.1 | T26: =IFERROR(E26*P26,"") -> 410.98901 | U26: =IFERROR((P26/1000)^2*O26*1000,"") -> 132.96703 | V26: =IFERROR(IF(Q26<=$D$5,"OK","OVER"),"--") -> OK | W26: =TRIM(IF(I26="estimated","* Imax estimated","")&IF(ISNUMBER(Q26),IF(Q26>$D$5," | OVER BUDGET",""),"")&IF(ISNUMBER(R26),IF(R26>0.85," | >85% Imax",""),"")&IF(AND(ISNUMBER(G26),ISNUMBER(E26)),IF(G26-E26>0.5," | Wide Vf range",""),"")&IF(ISNUMBER(U26),IF(U26>250," | R>250mW: use 1206",""),"")) -> * Imax estimated
A27: 3 | B27: =IFERROR(INDEX(Catalog!$B:$B,MATCH(A27,Catalog!$A:$A,0)),"") -> Red | C27: =IFERROR(INDEX(Catalog!$C:$C,MATCH(A27,Catalog!$A:$A,0)),"") -> 1 | D27: =IFERROR(INDEX(Catalog!$D:$D,MATCH(A27,Catalog!$A:$A,0)),"") -> 625nm (620-630nm) | E27: =IFERROR(INDEX(Catalog!$E:$E,MATCH(A27,Catalog!$A:$A,0)),"") -> 2.2 | F27: =IFERROR(INDEX(Catalog!$F:$F,MATCH(A27,Catalog!$A:$A,0)),"") -> 2 | G27: =IFERROR(INDEX(Catalog!$G:$G,MATCH(A27,Catalog!$A:$A,0)),"") -> 2.6 | H27: =IFERROR(INDEX(Catalog!$H:$H,MATCH(A27,Catalog!$A:$A,0)),"") -> 250 | I27: =IFERROR(INDEX(Catalog!$I:$I,MATCH(A27,Catalog!$A:$A,0)),"") -> datasheet | J27: 4 | K27: =IFERROR(INDEX(Catalog!$N:$N,MATCH(A27,Catalog!$A:$A,0)),"") -> 0.26 | L27: 0.6 | M27: =IFERROR(H27*L27,"") -> 150 | N27: =IFERROR(($D$4-E27)/(M27/1000),"") -> 15.333333 | O27: {=IFERROR(INDEX($D$10:$BX$10,MATCH(MIN(ABS($D$10:$BX$10-N27)),ABS($D$10:$BX$10-N27),0)),N27)} -> 15 | P27: =IFERROR(($D$4-E27)/O27*1000,"") -> 153.33333 | Q27: =IFERROR(P27*J27,"") -> 613.33333 | R27: =IFERROR(P27/H27,"") -> 0.61333333 | S27: =IFERROR(P27/1000*O27,"") -> 2.3 | T27: =IFERROR(E27*P27,"") -> 337.33333 | U27: =IFERROR((P27/1000)^2*O27*1000,"") -> 352.66667 | V27: =IFERROR(IF(Q27<=$D$5,"OK","OVER"),"--") -> OVER | W27: =TRIM(IF(I27="estimated","* Imax estimated","")&IF(ISNUMBER(Q27),IF(Q27>$D$5," | OVER BUDGET",""),"")&IF(ISNUMBER(R27),IF(R27>0.85," | >85% Imax",""),"")&IF(AND(ISNUMBER(G27),ISNUMBER(E27)),IF(G27-E27>0.5," | Wide Vf range",""),"")&IF(ISNUMBER(U27),IF(U27>250," | R>250mW: use 1206",""),"")) -> | OVER BUDGET | R>250mW: use 1206
... A29: 6 | B29: =IFERROR(INDEX(Catalog!$B:$B,MATCH(A29,Catalog!$A:$A,0)),"") -> Red | C29: =IFERROR(INDEX(Catalog!$C:$C,MATCH(A29,Catalog!$A:$A,0)),"") -> 3 | D29: =IFERROR(INDEX(Catalog!$D:$D,MATCH(A29,Catalog!$A:$A,0)),"") -> 620nm (typ) | E29: =IFERROR(INDEX(Catalog!$E:$E,MATCH(A29,Catalog!$A:$A,0)),"") -> 2.2 | F29: =IFERROR(INDEX(Catalog!$F:$F,MATCH(A29,Catalog!$A:$A,0)),"") -> 2 | G29: =IFERROR(INDEX(Catalog!$G:$G,MATCH(A29,Catalog!$A:$A,0)),"") -> 2.6 | H29: =IFERROR(INDEX(Catalog!$H:$H,MATCH(A29,Catalog!$A:$A,0)),"") -> 200 | I29: =IFERROR(INDEX(Catalog!$I:$I,MATCH(A29,Catalog!$A:$A,0)),"") -> datasheet | J29: 4 | K29: =IFERROR(INDEX(Catalog!$N:$N,MATCH(A29,Catalog!$A:$A,0)),"") -> 0.32 | L29: 0.6 | M29: =IFERROR(H29*L29,"") -> 120 | N29: =IFERROR(($D$4-E29)/(M29/1000),"") -> 19.166667 | O29: {=IFERROR(INDEX($D$10:$BX$10,MATCH(MIN(ABS($D$10:$BX$10-N29)),ABS($D$10:$BX$10-N29),0)),N29)} -> 20 | P29: =IFERROR(($D$4-E29)/O29*1000,"") -> 115 | Q29: =IFERROR(P29*J29,"") -> 460 | R29: =IFERROR(P29/H29,"") -> 0.575 | S29: =IFERROR(P29/1000*O29,"") -> 2.3 | T29: =IFERROR(E29*P29,"") -> 253 | U29: =IFERROR((P29/1000)^2*O29*1000,"") -> 264.5 | V29: =IFERROR(IF(Q29<=$D$5,"OK","OVER"),"--") -> OK | W29: =TRIM(IF(I29="estimated","* Imax estimated","")&IF(ISNUMBER(Q29),IF(Q29>$D$5," | OVER BUDGET",""),"")&IF(ISNUMBER(R29),IF(R29>0.85," | >85% Imax",""),"")&IF(AND(ISNUMBER(G29),ISNUMBER(E29)),IF(G29-E29>0.5," | Wide Vf range",""),"")&IF(ISNUMBER(U29),IF(U29>250," | R>250mW: use 1206",""),"")) -> | R>250mW: use 1206
A30: Max single-group total current (worst case in table): | Q30: =IFERROR(MAX(Q15:Q29),"") -> 840 | R30: =IFERROR(IF(MAX(Q15:Q29)<=$D$5,"All groups within budget","Some groups exceed budget -- review column V"),"--") -> Some groups exceed budget -- review column V
A32: KEY: Blue text / light blue background = cells you enter or can change | Green text = looked up from Catalog sheet | Black text = calculated | Amber column O = suggested E24 resistor (override by typing your chosen value) | Column J (N LEDs) can also be changed
A34: Vf_max Headroom Check | D34: At worst-case Vf_max, current through R_E24 could be very low. Check here.
A35: Row | B35: R E24 (Ω) | C35: I @ Vf_max (mA) | D35: I @ Vf_typ (mA) | E35: Ratio max/typ | F35: Headroom note
A36: =A15 -> 1015 | B36: =O15 -> 91 | C36: =IFERROR(($D$4-G15)/O15*1000,"") -> 5.4945055 | D36: =P15 -> 18.681319 | E36: =IFERROR(C36/D36,"") -> 0.29411765 | F36: =IFERROR(IF(C36<1,"LED OFF at Vf_max",IF(C36<5,"Very dim at Vf_max",IF(E36<0.5,">50% brightness variation","Acceptable range"))),"--") -> >50% brightness variation
A37: =A16 -> 1015 | B37: =O16 -> 91 | C37: =IFERROR(($D$4-G16)/O16*1000,"") -> 5.4945055 | D37: =P16 -> 18.681319 | E37: =IFERROR(C37/D37,"") -> 0.29411765 | F37: =IFERROR(IF(C37<1,"LED OFF at Vf_max",IF(C37<5,"Very dim at Vf_max",IF(E37<0.5,">50% brightness variation","Acceptable range"))),"--") -> >50% brightness variation
A38: =A17 -> 1012 | B38: =O17 -> 24 | C38: =IFERROR(($D$4-G17)/O17*1000,"") -> 45.833333 | D38: =P17 -> 62.5 | E38: =IFERROR(C38/D38,"") -> 0.73333333 | F38: =IFERROR(IF(C38<1,"LED OFF at Vf_max",IF(C38<5,"Very dim at Vf_max",IF(E38<0.5,">50% brightness variation","Acceptable range"))),"--") -> Acceptable range
A39: =A18 -> 1012 | B39: =O18 -> 24 | C39: =IFERROR(($D$4-G18)/O18*1000,"") -> 45.833333 | D39: =P18 -> 62.5 | E39: =IFERROR(C39/D39,"") -> 0.73333333 | F39: =IFERROR(IF(C39<1,"LED OFF at Vf_max",IF(C39<5,"Very dim at Vf_max",IF(E39<0.5,">50% brightness variation","Acceptable range"))),"--") -> Acceptable range
A40: =A19 -> 4 | B40: =O19 -> 11 | C40: =IFERROR(($D$4-G19)/O19*1000,"") -> 118.18182 | D40: =P19 -> 140 | E40: =IFERROR(C40/D40,"") -> 0.84415584 | F40: =IFERROR(IF(C40<1,"LED OFF at Vf_max",IF(C40<5,"Very dim at Vf_max",IF(E40<0.5,">50% brightness variation","Acceptable range"))),"--") -> Acceptable range
A41: =A20 -> 4 | B41: =O20 -> 11 | C41: =IFERROR(($D$4-G20)/O20*1000,"") -> 118.18182 | D41: =P20 -> 140 | E41: =IFERROR(C41/D41,"") -> 0.84415584 | F41: =IFERROR(IF(C41<1,"LED OFF at Vf_max",IF(C41<5,"Very dim at Vf_max",IF(E41<0.5,">50% brightness variation","Acceptable range"))),"--") -> Acceptable range
A42: =A21 -> 2 | B42: =O21 -> 11 | C42: =IFERROR(($D$4-G21)/O21*1000,"") -> 118.18182 | D42: =P21 -> 140.90909 | E42: =IFERROR(C42/D42,"") -> 0.83870968 | F42: =IFERROR(IF(C42<1,"LED OFF at Vf_max",IF(C42<5,"Very dim at Vf_max",IF(E42<0.5,">50% brightness variation","Acceptable range"))),"--") -> Acceptable range
A43: =A22 -> 1014 | B43: =O22 -> 11 | C43: =IFERROR(($D$4-G22)/O22*1000,"") -> 90.909091 | D43: =P22 -> 118.18182 | E43: =IFERROR(C43/D43,"") -> 0.76923077 | F43: =IFERROR(IF(C43<1,"LED OFF at Vf_max",IF(C43<5,"Very dim at Vf_max",IF(E43<0.5,">50% brightness variation","Acceptable range"))),"--") -> Acceptable range
A44: =A23 -> 102 | B44: =O23 -> 11 | C44: =IFERROR(($D$4-G23)/O23*1000,"") -> 90.909091 | D44: =P23 -> 118.18182 | E44: =IFERROR(C44/D44,"") -> 0.76923077 | F44: =IFERROR(IF(C44<1,"LED OFF at Vf_max",IF(C44<5,"Very dim at Vf_max",IF(E44<0.5,">50% brightness variation","Acceptable range"))),"--") -> Acceptable range
A45: =A24 -> 1 | B45: =O24 -> 12 | C45: =IFERROR(($D$4-G24)/O24*1000,"") -> 108.33333 | D45: =P24 -> 141.66667 | E45: =IFERROR(C45/D45,"") -> 0.76470588 | F45: =IFERROR(IF(C45<1,"LED OFF at Vf_max",IF(C45<5,"Very dim at Vf_max",IF(E45<0.5,">50% brightness variation","Acceptable range"))),"--") -> Acceptable range
A46: =A25 -> 532 | B46: =O25 -> 75 | C46: =IFERROR(($D$4-G25)/O25*1000,"") -> 13.333333 | D46: =P25 -> 18.666667 | E46: =IFERROR(C46/D46,"") -> 0.71428571 | F46: =IFERROR(IF(C46<1,"LED OFF at Vf_max",IF(C46<5,"Very dim at Vf_max",IF(E46<0.5,">50% brightness variation","Acceptable range"))),"--") -> Acceptable range
A47: =A26 -> 783 | B47: =O26 -> 9.1 | C47: =IFERROR(($D$4-G26)/O26*1000,"") -> 76.923077 | D47: =P26 -> 120.87912 | E47: =IFERROR(C47/D47,"") -> 0.63636364 | F47: =IFERROR(IF(C47<1,"LED OFF at Vf_max",IF(C47<5,"Very dim at Vf_max",IF(E47<0.5,">50% brightness variation","Acceptable range"))),"--") -> Acceptable range
...
